2020-04-26 09:44:08,170 ERROR: Exception on /security/GOOGl [GET] [in c:\users\44738\documents\web\venv\lib\site-packages\flask\app.py:1891]
Traceback (most recent call last):
  File "c:\users\44738\documents\web\venv\lib\site-packages\flask\app.py", line 2446, in wsgi_app
    response = self.full_dispatch_request()
  File "c:\users\44738\documents\web\venv\lib\site-packages\flask\app.py", line 1951, in full_dispatch_request
    rv = self.handle_user_exception(e)
  File "c:\users\44738\documents\web\venv\lib\site-packages\flask\app.py", line 1820, in handle_user_exception
    reraise(exc_type, exc_value, tb)
  File "c:\users\44738\documents\web\venv\lib\site-packages\flask\_compat.py", line 39, in reraise
    raise value
  File "c:\users\44738\documents\web\venv\lib\site-packages\flask\app.py", line 1949, in full_dispatch_request
    rv = self.dispatch_request()
  File "c:\users\44738\documents\web\venv\lib\site-packages\flask\app.py", line 1935, in dispatch_request
    return self.view_functions[rule.endpoint](**req.view_args)
  File "c:\users\44738\documents\web\venv\lib\site-packages\flask_login\utils.py", line 272, in decorated_view
    return func(*args, **kwargs)
  File "C:\Users\44738\Documents\Web\app\main\routes.py", line 59, in security
    return render_template("security.html" , ticker = ticker, db_ticker = db_ticker)
  File "c:\users\44738\documents\web\venv\lib\site-packages\flask\templating.py", line 140, in render_template
    ctx.app,
  File "c:\users\44738\documents\web\venv\lib\site-packages\flask\templating.py", line 120, in _render
    rv = template.render(context)
  File "c:\users\44738\documents\web\venv\lib\site-packages\jinja2\environment.py", line 1090, in render
    self.environment.handle_exception()
  File "c:\users\44738\documents\web\venv\lib\site-packages\jinja2\environment.py", line 832, in handle_exception
    reraise(*rewrite_traceback_stack(source=source))
  File "c:\users\44738\documents\web\venv\lib\site-packages\jinja2\_compat.py", line 28, in reraise
    raise value.with_traceback(tb)
  File "C:\Users\44738\Documents\Web\app\templates\security.html", line 1, in top-level template code
    {% extends "base.html" %}
  File "C:\Users\44738\Documents\Web\app\templates\base.html", line 2, in top-level template code
    {% extends 'bootstrap/base.html' %}
  File "c:\users\44738\documents\web\venv\lib\site-packages\flask_bootstrap\templates\bootstrap\base.html", line 1, in top-level template code
    {% block doc -%}
  File "c:\users\44738\documents\web\venv\lib\site-packages\flask_bootstrap\templates\bootstrap\base.html", line 3, in block "doc"
    <html{% block html_attribs %}{% endblock html_attribs %}>
  File "c:\users\44738\documents\web\venv\lib\site-packages\flask_bootstrap\templates\bootstrap\base.html", line 11, in block "html"
    {%- endblock metas %}
  File "c:\users\44738\documents\web\venv\lib\site-packages\flask_bootstrap\templates\bootstrap\base.html", line 13, in block "body"
    {%- block styles %}
  File "C:\Users\44738\Documents\Web\app\templates\base.html", line 54, in block "content"
    {% block app_content %}{% endblock %}
  File "C:\Users\44738\Documents\Web\app\templates\security.html", line 33, in block "app_content"
    <p><a href="{{ url_for('follow', ticker=ticker) }}">Follow</a></p>
  File "c:\users\44738\documents\web\venv\lib\site-packages\flask\helpers.py", line 370, in url_for
    return appctx.app.handle_url_build_error(error, endpoint, values)
  File "c:\users\44738\documents\web\venv\lib\site-packages\flask\app.py", line 2215, in handle_url_build_error
    reraise(exc_type, exc_value, tb)
  File "c:\users\44738\documents\web\venv\lib\site-packages\flask\_compat.py", line 39, in reraise
    raise value
  File "c:\users\44738\documents\web\venv\lib\site-packages\flask\helpers.py", line 358, in url_for
    endpoint, values, method=method, force_external=external
  File "c:\users\44738\documents\web\venv\lib\site-packages\werkzeug\routing.py", line 2179, in build
    raise BuildError(endpoint, values, method, self)
werkzeug.routing.BuildError: Could not build url for endpoint 'follow' with values ['ticker']. Did you mean 'main.follow' instead?
2020-04-26 09:46:51,276 INFO: Project startup [in C:\Users\44738\Documents\Web\app\__init__.py:57]
2020-04-26 09:46:52,593 ERROR: Exception on /security/GOOGl [GET] [in c:\users\44738\documents\web\venv\lib\site-packages\flask\app.py:1891]
Traceback (most recent call last):
  File "c:\users\44738\documents\web\venv\lib\site-packages\flask\app.py", line 2446, in wsgi_app
    response = self.full_dispatch_request()
  File "c:\users\44738\documents\web\venv\lib\site-packages\flask\app.py", line 1951, in full_dispatch_request
    rv = self.handle_user_exception(e)
  File "c:\users\44738\documents\web\venv\lib\site-packages\flask\app.py", line 1820, in handle_user_exception
    reraise(exc_type, exc_value, tb)
  File "c:\users\44738\documents\web\venv\lib\site-packages\flask\_compat.py", line 39, in reraise
    raise value
  File "c:\users\44738\documents\web\venv\lib\site-packages\flask\app.py", line 1949, in full_dispatch_request
    rv = self.dispatch_request()
  File "c:\users\44738\documents\web\venv\lib\site-packages\flask\app.py", line 1935, in dispatch_request
    return self.view_functions[rule.endpoint](**req.view_args)
  File "c:\users\44738\documents\web\venv\lib\site-packages\flask_login\utils.py", line 272, in decorated_view
    return func(*args, **kwargs)
  File "C:\Users\44738\Documents\Web\app\main\routes.py", line 59, in security
    return render_template("security.html" , ticker = ticker, db_ticker = db_ticker)
  File "c:\users\44738\documents\web\venv\lib\site-packages\flask\templating.py", line 140, in render_template
    ctx.app,
  File "c:\users\44738\documents\web\venv\lib\site-packages\flask\templating.py", line 120, in _render
    rv = template.render(context)
  File "c:\users\44738\documents\web\venv\lib\site-packages\jinja2\environment.py", line 1090, in render
    self.environment.handle_exception()
  File "c:\users\44738\documents\web\venv\lib\site-packages\jinja2\environment.py", line 832, in handle_exception
    reraise(*rewrite_traceback_stack(source=source))
  File "c:\users\44738\documents\web\venv\lib\site-packages\jinja2\_compat.py", line 28, in reraise
    raise value.with_traceback(tb)
  File "C:\Users\44738\Documents\Web\app\templates\security.html", line 1, in top-level template code
    {% extends "base.html" %}
  File "C:\Users\44738\Documents\Web\app\templates\base.html", line 2, in top-level template code
    {% extends 'bootstrap/base.html' %}
  File "c:\users\44738\documents\web\venv\lib\site-packages\flask_bootstrap\templates\bootstrap\base.html", line 1, in top-level template code
    {% block doc -%}
  File "c:\users\44738\documents\web\venv\lib\site-packages\flask_bootstrap\templates\bootstrap\base.html", line 3, in block "doc"
    <html{% block html_attribs %}{% endblock html_attribs %}>
  File "c:\users\44738\documents\web\venv\lib\site-packages\flask_bootstrap\templates\bootstrap\base.html", line 11, in block "html"
    {%- endblock metas %}
  File "c:\users\44738\documents\web\venv\lib\site-packages\flask_bootstrap\templates\bootstrap\base.html", line 13, in block "body"
    {%- block styles %}
  File "C:\Users\44738\Documents\Web\app\templates\base.html", line 54, in block "content"
    {% block app_content %}{% endblock %}
  File "C:\Users\44738\Documents\Web\app\templates\security.html", line 33, in block "app_content"
    <p><a href="{{ url_for('follow', ticker=ticker) }}">Follow</a></p>
  File "c:\users\44738\documents\web\venv\lib\site-packages\flask\helpers.py", line 370, in url_for
    return appctx.app.handle_url_build_error(error, endpoint, values)
  File "c:\users\44738\documents\web\venv\lib\site-packages\flask\app.py", line 2215, in handle_url_build_error
    reraise(exc_type, exc_value, tb)
  File "c:\users\44738\documents\web\venv\lib\site-packages\flask\_compat.py", line 39, in reraise
    raise value
  File "c:\users\44738\documents\web\venv\lib\site-packages\flask\helpers.py", line 358, in url_for
    endpoint, values, method=method, force_external=external
  File "c:\users\44738\documents\web\venv\lib\site-packages\werkzeug\routing.py", line 2179, in build
    raise BuildError(endpoint, values, method, self)
werkzeug.routing.BuildError: Could not build url for endpoint 'follow' with values ['ticker']. Did you mean 'main.follow' instead?
2020-04-26 09:47:02,248 INFO: Project startup [in C:\Users\44738\Documents\Web\app\__init__.py:57]
