2020-04-26 11:09:33,946 ERROR: Exception on /index [GET] [in c:\users\44738\documents\web\venv\lib\site-packages\flask\app.py:1891]
Traceback (most recent call last):
  File "c:\users\44738\documents\web\venv\lib\site-packages\flask\app.py", line 2446, in wsgi_app
    response = self.full_dispatch_request()
  File "c:\users\44738\documents\web\venv\lib\site-packages\flask\app.py", line 1951, in full_dispatch_request
    rv = self.handle_user_exception(e)
  File "c:\users\44738\documents\web\venv\lib\site-packages\flask\app.py", line 1820, in handle_user_exception
    reraise(exc_type, exc_value, tb)
  File "c:\users\44738\documents\web\venv\lib\site-packages\flask\_compat.py", line 39, in reraise
    raise value
  File "c:\users\44738\documents\web\venv\lib\site-packages\flask\app.py", line 1949, in full_dispatch_request
    rv = self.dispatch_request()
  File "c:\users\44738\documents\web\venv\lib\site-packages\flask\app.py", line 1935, in dispatch_request
    return self.view_functions[rule.endpoint](**req.view_args)
  File "c:\users\44738\documents\web\venv\lib\site-packages\flask_login\utils.py", line 271, in decorated_view
    return current_app.login_manager.unauthorized()
  File "c:\users\44738\documents\web\venv\lib\site-packages\flask_login\login_manager.py", line 174, in unauthorized
    redirect_url = make_login_url(login_view, next_url=request.url)
  File "c:\users\44738\documents\web\venv\lib\site-packages\flask_login\utils.py", line 120, in login_url
    base = expand_login_view(login_view)
  File "c:\users\44738\documents\web\venv\lib\site-packages\flask_login\utils.py", line 97, in expand_login_view
    return url_for(login_view)
  File "c:\users\44738\documents\web\venv\lib\site-packages\flask\helpers.py", line 370, in url_for
    return appctx.app.handle_url_build_error(error, endpoint, values)
  File "c:\users\44738\documents\web\venv\lib\site-packages\flask\app.py", line 2215, in handle_url_build_error
    reraise(exc_type, exc_value, tb)
  File "c:\users\44738\documents\web\venv\lib\site-packages\flask\_compat.py", line 39, in reraise
    raise value
  File "c:\users\44738\documents\web\venv\lib\site-packages\flask\helpers.py", line 358, in url_for
    endpoint, values, method=method, force_external=external
  File "c:\users\44738\documents\web\venv\lib\site-packages\werkzeug\routing.py", line 2179, in build
    raise BuildError(endpoint, values, method, self)
werkzeug.routing.BuildError: Could not build url for endpoint 'login'. Did you mean 'auth.login' instead?
2020-04-26 11:28:45,023 INFO: Project startup [in C:\Users\44738\Documents\Web\app\__init__.py:63]
2020-04-26 11:36:00,948 INFO: Project startup [in C:\Users\44738\Documents\Web\app\__init__.py:63]
2020-04-26 11:37:01,508 INFO: Project startup [in C:\Users\44738\Documents\Web\app\__init__.py:63]
2020-04-26 12:03:31,429 INFO: Project startup [in C:\Users\44738\Documents\Web\app\__init__.py:63]
2020-04-26 12:11:54,313 INFO: Project startup [in C:\Users\44738\Documents\Web\app\__init__.py:63]
2020-04-26 12:12:03,911 INFO: Project startup [in C:\Users\44738\Documents\Web\app\__init__.py:63]
2020-04-27 10:49:17,189 INFO: Project startup [in C:\Users\44738\Documents\Web\app\__init__.py:63]
2020-04-27 10:51:20,298 INFO: Project startup [in C:\Users\44738\Documents\Web\app\__init__.py:63]
2020-04-27 10:57:29,756 INFO: Project startup [in C:\Users\44738\Documents\Web\app\__init__.py:63]
2020-04-27 11:34:40,285 INFO: Project startup [in C:\Users\44738\Documents\Web\app\__init__.py:63]
2020-04-27 11:34:45,904 ERROR: Exception on / [GET] [in c:\users\44738\documents\web\venv\lib\site-packages\flask\app.py:1891]
Traceback (most recent call last):
  File "c:\users\44738\documents\web\venv\lib\site-packages\sqlalchemy\util\_collections.py", line 1030, in __call__
    return self.registry[key]
KeyError: 20268

During handling of the above exception, another exception occurred:

Traceback (most recent call last):
  File "c:\users\44738\documents\web\venv\lib\site-packages\flask\app.py", line 2446, in wsgi_app
    response = self.full_dispatch_request()
  File "c:\users\44738\documents\web\venv\lib\site-packages\flask\app.py", line 1951, in full_dispatch_request
    rv = self.handle_user_exception(e)
  File "c:\users\44738\documents\web\venv\lib\site-packages\flask\app.py", line 1820, in handle_user_exception
    reraise(exc_type, exc_value, tb)
  File "c:\users\44738\documents\web\venv\lib\site-packages\flask\_compat.py", line 39, in reraise
    raise value
  File "c:\users\44738\documents\web\venv\lib\site-packages\flask\app.py", line 1947, in full_dispatch_request
    rv = self.preprocess_request()
  File "c:\users\44738\documents\web\venv\lib\site-packages\flask\app.py", line 2241, in preprocess_request
    rv = func()
  File "C:\Users\44738\Documents\Web\app\main\routes.py", line 20, in before_request
    if current_user.is_authenticated:
  File "c:\users\44738\documents\web\venv\lib\site-packages\werkzeug\local.py", line 347, in __getattr__
    return getattr(self._get_current_object(), name)
  File "c:\users\44738\documents\web\venv\lib\site-packages\werkzeug\local.py", line 306, in _get_current_object
    return self.__local()
  File "c:\users\44738\documents\web\venv\lib\site-packages\flask_login\utils.py", line 26, in <lambda>
    current_user = LocalProxy(lambda: _get_user())
  File "c:\users\44738\documents\web\venv\lib\site-packages\flask_login\utils.py", line 346, in _get_user
    current_app.login_manager._load_user()
  File "c:\users\44738\documents\web\venv\lib\site-packages\flask_login\login_manager.py", line 318, in _load_user
    user = self._user_callback(user_id)
  File "C:\Users\44738\Documents\Web\app\models.py", line 17, in load_user
    return User.query.get(int(id))
  File "c:\users\44738\documents\web\venv\lib\site-packages\flask_sqlalchemy\__init__.py", line 519, in __get__
    return type.query_class(mapper, session=self.sa.session())
  File "c:\users\44738\documents\web\venv\lib\site-packages\sqlalchemy\orm\scoping.py", line 78, in __call__
    return self.registry()
  File "c:\users\44738\documents\web\venv\lib\site-packages\sqlalchemy\util\_collections.py", line 1032, in __call__
    return self.registry.setdefault(key, self.createfunc())
  File "c:\users\44738\documents\web\venv\lib\site-packages\sqlalchemy\orm\session.py", line 3254, in __call__
    return self.class_(**local_kw)
  File "c:\users\44738\documents\web\venv\lib\site-packages\flask_sqlalchemy\__init__.py", line 138, in __init__
    bind = options.pop('bind', None) or db.engine
  File "c:\users\44738\documents\web\venv\lib\site-packages\flask_sqlalchemy\__init__.py", line 937, in engine
    return self.get_engine()
  File "c:\users\44738\documents\web\venv\lib\site-packages\flask_sqlalchemy\__init__.py", line 956, in get_engine
    return connector.get_engine()
  File "c:\users\44738\documents\web\venv\lib\site-packages\flask_sqlalchemy\__init__.py", line 560, in get_engine
    options = self.get_options(sa_url, echo)
  File "c:\users\44738\documents\web\venv\lib\site-packages\flask_sqlalchemy\__init__.py", line 575, in get_options
    self._sa.apply_driver_hacks(self._app, sa_url, options)
  File "c:\users\44738\documents\web\venv\lib\site-packages\flask_sqlalchemy\__init__.py", line 877, in apply_driver_hacks
    if sa_url.drivername.startswith('mysql'):
AttributeError: 'NoneType' object has no attribute 'drivername'
2020-04-27 11:36:15,847 INFO: Project startup [in C:\Users\44738\Documents\Web\app\__init__.py:63]
