2020-12-23 10:10:29,565 ERROR: Exception on /skype [POST] [in C:\Users\44738\AppData\Local\Packages\PythonSoftwareFoundation.Python.3.7_qbz5n2kfra8p0\LocalCache\local-packages\Python37\site-packages\flask\app.py:1891]
Traceback (most recent call last):
  File "C:\Users\44738\AppData\Local\Packages\PythonSoftwareFoundation.Python.3.7_qbz5n2kfra8p0\LocalCache\local-packages\Python37\site-packages\flask\app.py", line 2446, in wsgi_app
    response = self.full_dispatch_request()
  File "C:\Users\44738\AppData\Local\Packages\PythonSoftwareFoundation.Python.3.7_qbz5n2kfra8p0\LocalCache\local-packages\Python37\site-packages\flask\app.py", line 1951, in full_dispatch_request
    rv = self.handle_user_exception(e)
  File "C:\Users\44738\AppData\Local\Packages\PythonSoftwareFoundation.Python.3.7_qbz5n2kfra8p0\LocalCache\local-packages\Python37\site-packages\flask_cors\extension.py", line 165, in wrapped_function
    return cors_after_request(app.make_response(f(*args, **kwargs)))
  File "C:\Users\44738\AppData\Local\Packages\PythonSoftwareFoundation.Python.3.7_qbz5n2kfra8p0\LocalCache\local-packages\Python37\site-packages\flask\app.py", line 1820, in handle_user_exception
    reraise(exc_type, exc_value, tb)
  File "C:\Users\44738\AppData\Local\Packages\PythonSoftwareFoundation.Python.3.7_qbz5n2kfra8p0\LocalCache\local-packages\Python37\site-packages\flask\_compat.py", line 39, in reraise
    raise value
  File "C:\Users\44738\AppData\Local\Packages\PythonSoftwareFoundation.Python.3.7_qbz5n2kfra8p0\LocalCache\local-packages\Python37\site-packages\flask\app.py", line 1949, in full_dispatch_request
    rv = self.dispatch_request()
  File "C:\Users\44738\AppData\Local\Packages\PythonSoftwareFoundation.Python.3.7_qbz5n2kfra8p0\LocalCache\local-packages\Python37\site-packages\flask\app.py", line 1935, in dispatch_request
    return self.view_functions[rule.endpoint](**req.view_args)
  File "C:\Users\44738\AppData\Local\Packages\PythonSoftwareFoundation.Python.3.7_qbz5n2kfra8p0\LocalCache\local-packages\Python37\site-packages\flask_login\utils.py", line 272, in decorated_view
    return func(*args, **kwargs)
  File "C:\Users\44738\OneDrive\Documents\Web\app\main\routes.py", line 94, in skype
    skypeSession.receive_message(selected)
  File "C:\Users\44738\OneDrive\Documents\Web\app\skype.py", line 84, in receive_message
    new_msgs = self.useToken.chats["8:" +  recepient].getMsgs()
  File "C:\Users\44738\AppData\Local\Packages\PythonSoftwareFoundation.Python.3.7_qbz5n2kfra8p0\LocalCache\local-packages\Python37\site-packages\skpy\chat.py", line 71, in getMsgs
    resp = self.skype.conn.syncStateCall("GET", url, params, auth=SkypeConnection.Auth.RegToken, headers=headers).json()
  File "C:\Users\44738\AppData\Local\Packages\PythonSoftwareFoundation.Python.3.7_qbz5n2kfra8p0\LocalCache\local-packages\Python37\site-packages\skpy\conn.py", line 261, in syncStateCall
    resp = self(method, url, params=params, **kwargs)
  File "C:\Users\44738\AppData\Local\Packages\PythonSoftwareFoundation.Python.3.7_qbz5n2kfra8p0\LocalCache\local-packages\Python37\site-packages\skpy\conn.py", line 237, in __call__
    raise SkypeApiException("{0} response from {1} {2}".format(resp.status_code, method, url), resp)
skpy.core.SkypeApiException: ('404 response from GET https://azscus1-client-s.gateway.messenger.live.com/v1/users/ME/conversations/8:evgenii.dimchenko/messages', <Response [404]>)
2020-12-23 10:10:49,856 ERROR: Exception on /messages/nickdimch [GET] [in C:\Users\44738\AppData\Local\Packages\PythonSoftwareFoundation.Python.3.7_qbz5n2kfra8p0\LocalCache\local-packages\Python37\site-packages\flask\app.py:1891]
Traceback (most recent call last):
  File "C:\Users\44738\AppData\Local\Packages\PythonSoftwareFoundation.Python.3.7_qbz5n2kfra8p0\LocalCache\local-packages\Python37\site-packages\flask\app.py", line 2446, in wsgi_app
    response = self.full_dispatch_request()
  File "C:\Users\44738\AppData\Local\Packages\PythonSoftwareFoundation.Python.3.7_qbz5n2kfra8p0\LocalCache\local-packages\Python37\site-packages\flask\app.py", line 1951, in full_dispatch_request
    rv = self.handle_user_exception(e)
  File "C:\Users\44738\AppData\Local\Packages\PythonSoftwareFoundation.Python.3.7_qbz5n2kfra8p0\LocalCache\local-packages\Python37\site-packages\flask_cors\extension.py", line 165, in wrapped_function
    return cors_after_request(app.make_response(f(*args, **kwargs)))
  File "C:\Users\44738\AppData\Local\Packages\PythonSoftwareFoundation.Python.3.7_qbz5n2kfra8p0\LocalCache\local-packages\Python37\site-packages\flask\app.py", line 1820, in handle_user_exception
    reraise(exc_type, exc_value, tb)
  File "C:\Users\44738\AppData\Local\Packages\PythonSoftwareFoundation.Python.3.7_qbz5n2kfra8p0\LocalCache\local-packages\Python37\site-packages\flask\_compat.py", line 39, in reraise
    raise value
  File "C:\Users\44738\AppData\Local\Packages\PythonSoftwareFoundation.Python.3.7_qbz5n2kfra8p0\LocalCache\local-packages\Python37\site-packages\flask\app.py", line 1949, in full_dispatch_request
    rv = self.dispatch_request()
  File "C:\Users\44738\AppData\Local\Packages\PythonSoftwareFoundation.Python.3.7_qbz5n2kfra8p0\LocalCache\local-packages\Python37\site-packages\flask\app.py", line 1935, in dispatch_request
    return self.view_functions[rule.endpoint](**req.view_args)
  File "C:\Users\44738\AppData\Local\Packages\PythonSoftwareFoundation.Python.3.7_qbz5n2kfra8p0\LocalCache\local-packages\Python37\site-packages\flask_login\utils.py", line 272, in decorated_view
    return func(*args, **kwargs)
  File "C:\Users\44738\OneDrive\Documents\Web\app\main\routes.py", line 102, in messages
    skypeSession.receive_message([user_id])
  File "C:\Users\44738\OneDrive\Documents\Web\app\skype.py", line 84, in receive_message
    new_msgs = self.useToken.chats["8:" +  recepient].getMsgs()
  File "C:\Users\44738\AppData\Local\Packages\PythonSoftwareFoundation.Python.3.7_qbz5n2kfra8p0\LocalCache\local-packages\Python37\site-packages\skpy\chat.py", line 71, in getMsgs
    resp = self.skype.conn.syncStateCall("GET", url, params, auth=SkypeConnection.Auth.RegToken, headers=headers).json()
  File "C:\Users\44738\AppData\Local\Packages\PythonSoftwareFoundation.Python.3.7_qbz5n2kfra8p0\LocalCache\local-packages\Python37\site-packages\skpy\conn.py", line 261, in syncStateCall
    resp = self(method, url, params=params, **kwargs)
  File "C:\Users\44738\AppData\Local\Packages\PythonSoftwareFoundation.Python.3.7_qbz5n2kfra8p0\LocalCache\local-packages\Python37\site-packages\skpy\conn.py", line 237, in __call__
    raise SkypeApiException("{0} response from {1} {2}".format(resp.status_code, method, url), resp)
skpy.core.SkypeApiException: ('404 response from GET https://azscus1-client-s.gateway.messenger.live.com/v1/users/ME/conversations/8:nickdimch/messages', <Response [404]>)
