2020-04-27 11:41:56,708 ERROR: Exception on /logout [GET] [in c:\users\44738\documents\web\venv\lib\site-packages\flask\app.py:1891]
Traceback (most recent call last):
  File "c:\users\44738\documents\web\venv\lib\site-packages\flask\app.py", line 1949, in full_dispatch_request
    rv = self.dispatch_request()
  File "c:\users\44738\documents\web\venv\lib\site-packages\flask\app.py", line 1925, in dispatch_request
    self.raise_routing_exception(req)
  File "c:\users\44738\documents\web\venv\lib\site-packages\flask\app.py", line 1907, in raise_routing_exception
    raise request.routing_exception
  File "c:\users\44738\documents\web\venv\lib\site-packages\flask\ctx.py", line 350, in match_request
    result = self.url_adapter.match(return_rule=True)
  File "c:\users\44738\documents\web\venv\lib\site-packages\werkzeug\routing.py", line 1945, in match
    raise NotFound()
werkzeug.exceptions.NotFound: 404 Not Found: The requested URL was not found on the server. If you entered the URL manually please check your spelling and try again.

During handling of the above exception, another exception occurred:

Traceback (most recent call last):
  File "c:\users\44738\documents\web\venv\lib\site-packages\sqlalchemy\engine\base.py", line 1248, in _execute_context
    cursor, statement, parameters, context
  File "c:\users\44738\documents\web\venv\lib\site-packages\sqlalchemy\engine\default.py", line 588, in do_execute
    cursor.execute(statement, parameters)
sqlite3.OperationalError: no such column: user.last_seen

The above exception was the direct cause of the following exception:

Traceback (most recent call last):
  File "c:\users\44738\documents\web\venv\lib\site-packages\flask\app.py", line 2446, in wsgi_app
    response = self.full_dispatch_request()
  File "c:\users\44738\documents\web\venv\lib\site-packages\flask\app.py", line 1951, in full_dispatch_request
    rv = self.handle_user_exception(e)
  File "c:\users\44738\documents\web\venv\lib\site-packages\flask\app.py", line 1815, in handle_user_exception
    return self.handle_http_exception(e)
  File "c:\users\44738\documents\web\venv\lib\site-packages\flask\app.py", line 1743, in handle_http_exception
    return handler(e)
  File "C:\Users\44738\Documents\Web\app\errors\handlers.py", line 7, in not_found_error
    return render_template('errors/404.html'),404
  File "c:\users\44738\documents\web\venv\lib\site-packages\flask\templating.py", line 136, in render_template
    ctx.app.update_template_context(context)
  File "c:\users\44738\documents\web\venv\lib\site-packages\flask\app.py", line 838, in update_template_context
    context.update(func())
  File "c:\users\44738\documents\web\venv\lib\site-packages\flask_login\utils.py", line 379, in _user_context_processor
    return dict(current_user=_get_user())
  File "c:\users\44738\documents\web\venv\lib\site-packages\flask_login\utils.py", line 346, in _get_user
    current_app.login_manager._load_user()
  File "c:\users\44738\documents\web\venv\lib\site-packages\flask_login\login_manager.py", line 318, in _load_user
    user = self._user_callback(user_id)
  File "C:\Users\44738\Documents\Web\app\models.py", line 17, in load_user
    return User.query.get(int(id))
  File "c:\users\44738\documents\web\venv\lib\site-packages\sqlalchemy\orm\query.py", line 1004, in get
    return self._get_impl(ident, loading.load_on_pk_identity)
  File "c:\users\44738\documents\web\venv\lib\site-packages\sqlalchemy\orm\query.py", line 1119, in _get_impl
    return db_load_fn(self, primary_key_identity)
  File "c:\users\44738\documents\web\venv\lib\site-packages\sqlalchemy\orm\loading.py", line 284, in load_on_pk_identity
    return q.one()
  File "c:\users\44738\documents\web\venv\lib\site-packages\sqlalchemy\orm\query.py", line 3358, in one
    ret = self.one_or_none()
  File "c:\users\44738\documents\web\venv\lib\site-packages\sqlalchemy\orm\query.py", line 3327, in one_or_none
    ret = list(self)
  File "c:\users\44738\documents\web\venv\lib\site-packages\sqlalchemy\orm\query.py", line 3403, in __iter__
    return self._execute_and_instances(context)
  File "c:\users\44738\documents\web\venv\lib\site-packages\sqlalchemy\orm\query.py", line 3428, in _execute_and_instances
    result = conn.execute(querycontext.statement, self._params)
  File "c:\users\44738\documents\web\venv\lib\site-packages\sqlalchemy\engine\base.py", line 984, in execute
    return meth(self, multiparams, params)
  File "c:\users\44738\documents\web\venv\lib\site-packages\sqlalchemy\sql\elements.py", line 293, in _execute_on_connection
    return connection._execute_clauseelement(self, multiparams, params)
  File "c:\users\44738\documents\web\venv\lib\site-packages\sqlalchemy\engine\base.py", line 1103, in _execute_clauseelement
    distilled_params,
  File "c:\users\44738\documents\web\venv\lib\site-packages\sqlalchemy\engine\base.py", line 1288, in _execute_context
    e, statement, parameters, cursor, context
  File "c:\users\44738\documents\web\venv\lib\site-packages\sqlalchemy\engine\base.py", line 1482, in _handle_dbapi_exception
    sqlalchemy_exception, with_traceback=exc_info[2], from_=e
  File "c:\users\44738\documents\web\venv\lib\site-packages\sqlalchemy\util\compat.py", line 178, in raise_
    raise exception
  File "c:\users\44738\documents\web\venv\lib\site-packages\sqlalchemy\engine\base.py", line 1248, in _execute_context
    cursor, statement, parameters, context
  File "c:\users\44738\documents\web\venv\lib\site-packages\sqlalchemy\engine\default.py", line 588, in do_execute
    cursor.execute(statement, parameters)
sqlalchemy.exc.OperationalError: (sqlite3.OperationalError) no such column: user.last_seen
[SQL: SELECT user.id AS user_id, user.username AS user_username, user.password_hash AS user_password_hash, user.email AS user_email, user.last_seen AS user_last_seen 
FROM user 
WHERE user.id = ?]
[parameters: (2,)]
(Background on this error at: http://sqlalche.me/e/e3q8)
2020-04-27 11:42:12,669 INFO: Project startup [in C:\Users\44738\Documents\Web\app\__init__.py:63]
2020-04-27 11:42:23,788 INFO: Project startup [in C:\Users\44738\Documents\Web\app\__init__.py:63]
2020-04-27 11:53:27,094 INFO: Project startup [in C:\Users\44738\Documents\Web\app\__init__.py:63]
2020-04-27 11:54:14,332 INFO: Project startup [in C:\Users\44738\Documents\Web\app\__init__.py:63]
2020-04-27 11:54:36,447 INFO: Project startup [in C:\Users\44738\Documents\Web\app\__init__.py:63]
2020-04-27 11:54:48,884 INFO: Project startup [in C:\Users\44738\Documents\Web\app\__init__.py:63]
2020-04-27 11:55:17,440 INFO: Project startup [in C:\Users\44738\Documents\Web\app\__init__.py:63]
2020-04-27 11:55:33,306 INFO: Project startup [in C:\Users\44738\Documents\Web\app\__init__.py:63]
2020-04-27 11:55:52,079 INFO: Project startup [in C:\Users\44738\Documents\Web\app\__init__.py:63]
2020-04-27 11:55:58,250 INFO: Project startup [in C:\Users\44738\Documents\Web\app\__init__.py:63]
2020-04-27 13:41:02,978 INFO: Project startup [in C:\Users\44738\Documents\Web\app\__init__.py:63]
2020-04-27 13:41:13,657 INFO: Project startup [in C:\Users\44738\Documents\Web\app\__init__.py:63]
2020-04-27 13:41:25,205 INFO: Project startup [in C:\Users\44738\Documents\Web\app\__init__.py:63]
2020-04-27 13:41:49,163 INFO: Project startup [in C:\Users\44738\Documents\Web\app\__init__.py:63]
2020-04-27 14:18:50,864 INFO: Project startup [in C:\Users\44738\Documents\Web\app\__init__.py:63]
2020-04-27 14:18:59,927 INFO: Project startup [in C:\Users\44738\Documents\Web\app\__init__.py:63]
2020-04-27 14:19:05,698 INFO: Project startup [in C:\Users\44738\Documents\Web\app\__init__.py:63]
2020-04-27 14:19:15,475 INFO: Project startup [in C:\Users\44738\Documents\Web\app\__init__.py:63]
2020-04-27 18:21:19,345 INFO: Project startup [in C:\Users\44738\Documents\Web\app\__init__.py:63]
2020-04-27 18:22:07,584 INFO: Project startup [in C:\Users\44738\Documents\Web\app\__init__.py:63]
2020-04-27 18:23:09,922 INFO: Project startup [in C:\Users\44738\Documents\Web\app\__init__.py:63]
2020-04-27 18:23:19,273 INFO: Project startup [in C:\Users\44738\Documents\Web\app\__init__.py:63]
2020-04-27 18:23:25,348 INFO: Project startup [in C:\Users\44738\Documents\Web\app\__init__.py:63]
